2024-06-09 13:08:43,187 ERROR scheduler Exception in Enqueue Events for Site mkulima_mdogo.com
Traceback (most recent call last):
  File "/home/ibrah/mkulima-mdogo/frappe-bench/apps/frappe/frappe/utils/scheduler.py", line 75, in enqueue_events_for_site
    if is_scheduler_inactive():
       ^^^^^^^^^^^^^^^^^^^^^^^
  File "/home/ibrah/mkulima-mdogo/frappe-bench/apps/frappe/frappe/utils/scheduler.py", line 117, in is_scheduler_inactive
    if is_scheduler_disabled(verbose=verbose):
       ^^^^^^^^^^^^^^^^^^^^^^^^^^^^^^^^^^^^^^
  File "/home/ibrah/mkulima-mdogo/frappe-bench/apps/frappe/frappe/utils/scheduler.py", line 130, in is_scheduler_disabled
    frappe.db.get_single_value("System Settings", "enable_scheduler")
  File "/home/ibrah/mkulima-mdogo/frappe-bench/apps/frappe/frappe/database/database.py", line 841, in get_single_value
    ).run()
      ^^^^^
  File "/home/ibrah/mkulima-mdogo/frappe-bench/apps/frappe/frappe/query_builder/utils.py", line 87, in execute_query
    result = frappe.db.sql(query, params, *args, **kwargs)  # nosemgrep
             ^^^^^^^^^^^^^^^^^^^^^^^^^^^^^^^^^^^^^^^^^^^^^
  File "/home/ibrah/mkulima-mdogo/frappe-bench/apps/frappe/frappe/database/database.py", line 211, in sql
    self.connect()
  File "/home/ibrah/mkulima-mdogo/frappe-bench/apps/frappe/frappe/database/database.py", line 117, in connect
    self._conn: "MariadbConnection" | "PostgresConnection" = self.get_connection()
                                                             ^^^^^^^^^^^^^^^^^^^^^
  File "/home/ibrah/mkulima-mdogo/frappe-bench/apps/frappe/frappe/database/mariadb/database.py", line 107, in get_connection
    conn = self._get_connection()
           ^^^^^^^^^^^^^^^^^^^^^^
  File "/home/ibrah/mkulima-mdogo/frappe-bench/apps/frappe/frappe/database/mariadb/database.py", line 113, in _get_connection
    return self.create_connection()
           ^^^^^^^^^^^^^^^^^^^^^^^^
  File "/home/ibrah/mkulima-mdogo/frappe-bench/apps/frappe/frappe/database/mariadb/database.py", line 116, in create_connection
    return pymysql.connect(**self.get_connection_settings())
           ^^^^^^^^^^^^^^^^^^^^^^^^^^^^^^^^^^^^^^^^^^^^^^^^^
  File "/home/ibrah/mkulima-mdogo/frappe-bench/env/lib/python3.12/site-packages/pymysql/connections.py", line 361, in __init__
    self.connect()
  File "/home/ibrah/mkulima-mdogo/frappe-bench/env/lib/python3.12/site-packages/pymysql/connections.py", line 669, in connect
    self._request_authentication()
  File "/home/ibrah/mkulima-mdogo/frappe-bench/env/lib/python3.12/site-packages/pymysql/connections.py", line 957, in _request_authentication
    auth_packet = self._read_packet()
                  ^^^^^^^^^^^^^^^^^^^
  File "/home/ibrah/mkulima-mdogo/frappe-bench/env/lib/python3.12/site-packages/pymysql/connections.py", line 775, in _read_packet
    packet.raise_for_error()
  File "/home/ibrah/mkulima-mdogo/frappe-bench/env/lib/python3.12/site-packages/pymysql/protocol.py", line 219, in raise_for_error
    err.raise_mysql_exception(self._data)
  File "/home/ibrah/mkulima-mdogo/frappe-bench/env/lib/python3.12/site-packages/pymysql/err.py", line 150, in raise_mysql_exception
    raise errorclass(errno, errval)
pymysql.err.OperationalError: (1045, "Access denied for user 'mkulima_mdogo'@'localhost' (using password: YES)")
2024-06-09 13:09:43,198 ERROR scheduler Exception in Enqueue Events for Site mkulima_mdogo.com
Traceback (most recent call last):
  File "/home/ibrah/mkulima-mdogo/frappe-bench/apps/frappe/frappe/utils/scheduler.py", line 75, in enqueue_events_for_site
    if is_scheduler_inactive():
       ^^^^^^^^^^^^^^^^^^^^^^^
  File "/home/ibrah/mkulima-mdogo/frappe-bench/apps/frappe/frappe/utils/scheduler.py", line 117, in is_scheduler_inactive
    if is_scheduler_disabled(verbose=verbose):
       ^^^^^^^^^^^^^^^^^^^^^^^^^^^^^^^^^^^^^^
  File "/home/ibrah/mkulima-mdogo/frappe-bench/apps/frappe/frappe/utils/scheduler.py", line 130, in is_scheduler_disabled
    frappe.db.get_single_value("System Settings", "enable_scheduler")
  File "/home/ibrah/mkulima-mdogo/frappe-bench/apps/frappe/frappe/database/database.py", line 841, in get_single_value
    ).run()
      ^^^^^
  File "/home/ibrah/mkulima-mdogo/frappe-bench/apps/frappe/frappe/query_builder/utils.py", line 87, in execute_query
    result = frappe.db.sql(query, params, *args, **kwargs)  # nosemgrep
             ^^^^^^^^^^^^^^^^^^^^^^^^^^^^^^^^^^^^^^^^^^^^^
  File "/home/ibrah/mkulima-mdogo/frappe-bench/apps/frappe/frappe/database/database.py", line 211, in sql
    self.connect()
  File "/home/ibrah/mkulima-mdogo/frappe-bench/apps/frappe/frappe/database/database.py", line 117, in connect
    self._conn: "MariadbConnection" | "PostgresConnection" = self.get_connection()
                                                             ^^^^^^^^^^^^^^^^^^^^^
  File "/home/ibrah/mkulima-mdogo/frappe-bench/apps/frappe/frappe/database/mariadb/database.py", line 107, in get_connection
    conn = self._get_connection()
           ^^^^^^^^^^^^^^^^^^^^^^
  File "/home/ibrah/mkulima-mdogo/frappe-bench/apps/frappe/frappe/database/mariadb/database.py", line 113, in _get_connection
    return self.create_connection()
           ^^^^^^^^^^^^^^^^^^^^^^^^
  File "/home/ibrah/mkulima-mdogo/frappe-bench/apps/frappe/frappe/database/mariadb/database.py", line 116, in create_connection
    return pymysql.connect(**self.get_connection_settings())
           ^^^^^^^^^^^^^^^^^^^^^^^^^^^^^^^^^^^^^^^^^^^^^^^^^
  File "/home/ibrah/mkulima-mdogo/frappe-bench/env/lib/python3.12/site-packages/pymysql/connections.py", line 361, in __init__
    self.connect()
  File "/home/ibrah/mkulima-mdogo/frappe-bench/env/lib/python3.12/site-packages/pymysql/connections.py", line 669, in connect
    self._request_authentication()
  File "/home/ibrah/mkulima-mdogo/frappe-bench/env/lib/python3.12/site-packages/pymysql/connections.py", line 957, in _request_authentication
    auth_packet = self._read_packet()
                  ^^^^^^^^^^^^^^^^^^^
  File "/home/ibrah/mkulima-mdogo/frappe-bench/env/lib/python3.12/site-packages/pymysql/connections.py", line 775, in _read_packet
    packet.raise_for_error()
  File "/home/ibrah/mkulima-mdogo/frappe-bench/env/lib/python3.12/site-packages/pymysql/protocol.py", line 219, in raise_for_error
    err.raise_mysql_exception(self._data)
  File "/home/ibrah/mkulima-mdogo/frappe-bench/env/lib/python3.12/site-packages/pymysql/err.py", line 150, in raise_mysql_exception
    raise errorclass(errno, errval)
pymysql.err.OperationalError: (1045, "Access denied for user 'mkulima_mdogo'@'localhost' (using password: YES)")
2024-06-18 11:15:02,755 ERROR scheduler Skipped queueing frappe.website.doctype.web_page.web_page.check_publish_status because it was found in queue for mkulima_mdogo.com
